<?xml version="1.0"?>
<robot name="simple_robot" xmlns:xacro="http://www.ros.org/wiki/xacro">

  <!-- ===================== 材料定义 (全局复用) ===================== -->
  <material name="blue">
    <color rgba="0.2 0.7 0.3 1.0"/>
  </material>
  <material name="black">
    <color rgba="0.0 0.0 0.0 1.0"/>
  </material>
  <material name="gray">
    <color rgba="0.5 0.5 0.5 1.0"/>
  </material>

  <!-- ===================== 基础底盘 ===================== -->
  <link name="base_footprint"/>
  <joint name="base_footprint_joint" type="fixed">
    <parent link="base_footprint"/>
    <child link="base_link"/>
    <origin xyz="0 0 0.05" rpy="0 0 0"/>
  </joint>

  <link name="base_link">
    <visual>
      <geometry>
        <box size="0.3 0.2 0.1"/>
      </geometry>
      <material name="blue"/>
    </visual>

    <collision>
      <geometry>
        <box size="0.3 0.2 0.1"/>
      </geometry>
    </collision>

    <inertial>
      <mass value="5.0"/>
      <inertia ixx="0.1" ixy="0.0" ixz="0.0" iyy="0.2" iyz="0.0" izz="0.3"/>
    </inertial>
  </link>

  <!-- ===================== 轮子宏定义 (左右轮复用) ===================== -->
  <xacro:macro name="wheel_macro" params="name parent_link x y z">
    <link name="${name}_link">
      <visual>
        <geometry>
          <cylinder radius="0.05" length="0.04"/>
        </geometry>
        <material name="black"/>
      </visual>

      <collision>
        <geometry>
          <cylinder radius="0.05" length="0.04"/>
        </geometry>
      </collision>

      <inertial>
        <mass value="0.5"/>
        <inertia ixx="0.0001" ixy="0" ixz="0" iyy="0.0001" iyz="0" izz="0.0001"/>
      </inertial>
    </link>

    <joint name="${name}_joint" type="continuous">
      <parent link="${parent_link}"/>
      <child link="${name}_link"/>
      <origin xyz="${x} ${y} ${z}" rpy="0 1.5708 1.5708"/>
      <axis xyz="0 0 1"/>
    </joint>
  </xacro:macro>

  <!-- 实例化左右驱动轮 -->
  <xacro:wheel_macro name="wheel_left" parent_link="base_link" x="-0.1" y="0.12" z="-0.02"/>
  <xacro:wheel_macro name="wheel_right" parent_link="base_link" x="-0.1" y="-0.12" z="-0.02"/>

  <!-- ===================== 万向轮 ===================== -->
  <link name="caster_link">
    <visual>
      <geometry>
        <sphere radius="0.03"/>
      </geometry>
      <material name="gray"/>
    </visual>

    <collision>
      <geometry>
        <sphere radius="0.03"/>
      </geometry>
    </collision>

    <inertial>
      <mass value="0.3"/>
      <inertia ixx="0.0001" ixy="0" ixz="0" iyy="0.0001" iyz="0" izz="0.0001"/>
    </inertial>
  </link>

  <joint name="caster_joint" type="fixed">
    <parent link="base_link"/>
    <child link="caster_link"/>
    <origin xyz="0.1 0 -0.04"/>
  </joint>

  <!-- ===================== Gazebo 差速控制器 ===================== -->
  <gazebo>
    <plugin name="differential_drive_controller" filename="libgazebo_ros_diff_drive.so">
      <alwaysOn>true</alwaysOn>
      <leftJoint>wheel_left_joint</leftJoint>
      <rightJoint>wheel_right_joint</rightJoint>
      <wheelSeparation>0.24</wheelSeparation>
      <wheelDiameter>0.1</wheelDiameter>
      <torque>10</torque>
      <commandTopic>cmd_vel</commandTopic>
      <odometryTopic>odom</odometryTopic>
      <odometryFrame>odom</odometryFrame>
      <robotBaseFrame>base_link</robotBaseFrame>
    </plugin>
  </gazebo>

</robot>