<?xml version="1.0"?>
<robot xmlns:xacro="http://www.ros.org/wiki/xacro">

  <xacro:macro name="wheel_macro" params="name parent_link x y z">
    <link name="${name}_link">
      <visual>
        <geometry>
          <cylinder radius="0.05" length="0.04"/>
        </geometry>
        <material name="black"/>
      </visual>
      <collision>
        <geometry>
          <cylinder radius="0.05" length="0.04"/>
        </geometry>
      </collision>
      <inertial>
        <mass value="0.5"/>
        <inertia ixx="0.0001" ixy="0" ixz="0" iyy="0.0001" iyz="0" izz="0.0001"/>
      </inertial>
    </link>

    <joint name="${name}_joint" type="continuous">
      <parent link="${parent_link}"/>
      <child link="${name}_link"/>
      <origin xyz="${x} ${y} ${z}" rpy="0 1.5708 1.5708"/>
      <axis xyz="0 0 1"/>
    </joint>
  </xacro:macro>
  <xacro:wheel_macro name="wheel_left" parent_link="base_link" x="-0.1" y="0.12" z="-0.02"/>
  <xacro:wheel_macro name="wheel_right" parent_link="base_link" x="-0.1" y="-0.12" z="-0.02"/>

  <link name="caster_link">
    <visual>
      <geometry>
        <sphere radius="0.03"/>
      </geometry>
      <material name="gray"/>
    </visual>
    <collision>
      <geometry>
        <sphere radius="0.03"/>
      </geometry>
    </collision>
    <inertial>
      <mass value="0.3"/>
      <inertia ixx="0.0001" ixy="0" ixz="0" iyy="0.0001" iyz="0" izz="0.0001"/>
    </inertial>
  </link>

  <joint name="caster_joint" type="fixed">
    <parent link="base_link"/>
    <child link="caster_link"/>
    <origin xyz="0.1 0 -0.04"/>
  </joint>

</robot>